<?xml version="1.0" ?>
<!-- =================================================================================== -->
<!-- |    This document was autogenerated by xacro from ayg.xacro                      | -->
<!-- |    EDITING THIS FILE BY HAND IS NOT RECOMMENDED                                 | -->
<!-- =================================================================================== -->
<robot name="ayg">
  <link name="Base">
    <inertial>
      <origin rpy="0 0 0" xyz="0.000442764791303709 0.00323410160779704 0.000245694936587104"/>
      <mass value="8.43904999246817"/>
      <inertia ixx="0.020065303439704" ixy="4.08404656288191E-05" ixz="-2.29078687506071E-14" iyy="0.0384358501598642" iyz="-2.71859452435122E-15" izz="0.0267905011857108"/>
    </inertial>
    <visual>
      <origin rpy="0 0 0" xyz="0 0 0"/>
      <geometry>
        <mesh filename="package://ayg_description/meshes/Base.STL"/>
      </geometry>
      <material name="">
        <color rgba="0.698039215686274 0.698039215686274 0.698039215686274 1"/>
      </material>
    </visual>
    <collision>
      <origin rpy="0 0 0" xyz="0 0 0"/>
      <geometry>
        <box size="0.4 0.23 0.12"/>
      </geometry>
    </collision>
  </link>
  <link name="LF_Hip">
    <inertial>
      <origin rpy="0 0 0" xyz="0.0624625305028617 0.000263588472359728 -0.00241409757946361"/>
      <mass value="1.00401999005125"/>
      <inertia ixx="0.000584357699669872" ixy="1.71578981310067E-06" ixz="-2.61675027998363E-19" iyy="0.000584539401732687" iyz="-3.57751728713357E-20" izz="0.00102756652010595"/>
    </inertial>
    <visual>
      <origin rpy="0 0 0" xyz="0 0 0"/>
      <geometry>
        <mesh filename="package://ayg_description/meshes/L_Hip.STL"/>
      </geometry>
      <material name="">
        <color rgba="0.698039215686274 0.698039215686274 0.698039215686274 1"/>
      </material>
    </visual>
    <collision>
      <origin rpy="0 0 0" xyz="0 0 0"/>
      <geometry>
        <mesh filename="package://ayg_description/meshes/L_Hip.STL"/>
      </geometry>
    </collision>
  </link>
  <joint name="LF_HAA" type="revolute">
    <origin rpy="-1.5708 0 0" xyz="0.197 0.054 0"/>
    <parent link="Base"/>
    <child link="LF_Hip"/>
    <axis xyz="1 0 0"/>
    <limit effort="50.0" lower="-0.5236" upper="0.34907" velocity="10.0"/>
  </joint>
  <link name="LF_Thigh">
    <inertial>
      <origin rpy="0 0 0" xyz="-0.00815740476229621 -0.00912689407030123 -0.0420066354122466"/>
      <mass value="1.15974999242447"/>
      <inertia ixx="0.000911992879302287" ixy="-0.000310524680951164" ixz="-4.3266057977693E-16" iyy="0.00091897366461706" iyz="-1.93894477964206E-06" izz="0.00169326046596367"/>
    </inertial>
    <visual>
      <origin rpy="0 0 0" xyz="0 0 0"/>
      <geometry>
        <mesh filename="package://ayg_description/meshes/L_Thigh.STL"/>
      </geometry>
      <material name="">
        <color rgba="0.698039215686274 0.698039215686274 0.698039215686274 1"/>
      </material>
    </visual>
    <collision>
      <origin rpy="0 0 0" xyz="0 0 0"/>
      <geometry>
        <mesh filename="package://ayg_description/meshes/L_Thigh.STL"/>
      </geometry>
    </collision>
  </link>
  <joint name="LF_HFE" type="revolute">
    <origin rpy="3.1416 0 0" xyz="0.0665 0 0.019"/>
    <parent link="LF_Hip"/>
    <child link="LF_Thigh"/>
    <axis xyz="0 0 1"/>
    <limit effort="50.0" lower="-0.87266" upper="2.5307" velocity="10.0"/>
  </joint>
  <link name="LF_Shank">
    <inertial>
      <origin rpy="0 0 0" xyz="0.0630329536265654 -0.047817827674744 -0.0185"/>
      <mass value="0.102570008997248"/>
      <inertia ixx="0.00029767764878727" ixy="0.000296980915761884" ixz="1.63288326545704E-19" iyy="0.000327832614532812" iyz="-1.54063121876522E-19" izz="0.000624546801244392"/>
    </inertial>
    <visual>
      <origin rpy="0 0 0" xyz="0 0 0"/>
      <geometry>
        <mesh filename="package://ayg_description/meshes/L_Shank.STL"/>
      </geometry>
      <material name="">
        <color rgba="0.698039215686274 0.698039215686274 0.698039215686274 1"/>
      </material>
    </visual>
    <collision>
      <origin rpy="0 0 0" xyz="0 0 0"/>
      <geometry>
        <mesh filename="package://ayg_description/meshes/L_Shank.STL"/>
      </geometry>
    </collision>
  </link>
  <joint name="LF_KFE" type="revolute">
    <origin rpy="0 0 0" xyz="-0.14936 -0.16017 -0.052"/>
    <parent link="LF_Thigh"/>
    <child link="LF_Shank"/>
    <axis xyz="0 0 1"/>
    <limit effort="50.0" lower="-0.7854" upper="1.2217" velocity="10.0"/>
  </joint>
  <link name="LF_Foot">
    <inertial>
      <origin rpy="0 1.5707963267948966 0" xyz="-2.77555756156289E-17 5.55111512312578E-17 0"/>
      <mass value="0.088054927521184"/>
      <inertia ixx="4.09565481632907E-05" ixy="-8.61058027358505E-21" ixz="2.27932697045296E-20" iyy="2.47049106026622E-05" iyz="5.04870979341448E-29" izz="2.47049106026622E-05"/>
    </inertial>
    <visual>
      <origin rpy="0 0 0" xyz="0 0 0"/>
      <geometry>
        <cylinder length="0.025" radius="0.030"/>
      </geometry>
      <material name="">
        <color rgba="0.250980392156863 0.250980392156863 0.250980392156863 1"/>
      </material>
    </visual>
    <collision>
      <origin rpy="0 0 0" xyz="0 0 0"/>
      <geometry>
        <cylinder length="0.025" radius="0.030"/>
      </geometry>
    </collision>
  </link>
  <joint name="LF_Shank_2_Foot" type="fixed">
    <origin rpy="0 0 0" xyz="0.165 -0.151 -0.0185"/>
    <parent link="LF_Shank"/>
    <child link="LF_Foot"/>
    <axis xyz="0 0 0"/>
  </joint>
  <link name="RF_Hip">
    <inertial>
      <origin rpy="0 0 0" xyz="0.062462530502862 0.000263588472360484 0.00241409757946365"/>
      <mass value="1.00401999005125"/>
      <inertia ixx="0.000584357699669871" ixy="1.71578981310067E-06" ixz="-3.08533699148142E-19" iyy="0.000584539401732687" iyz="1.3310433650471E-20" izz="0.00102756652010595"/>
    </inertial>
    <visual>
      <origin rpy="0 0 0" xyz="0 0 0"/>
      <geometry>
        <mesh filename="package://ayg_description/meshes/R_Hip.STL"/>
      </geometry>
      <material name="">
        <color rgba="0.698039215686274 0.698039215686274 0.698039215686274 1"/>
      </material>
    </visual>
    <collision>
      <origin rpy="0 0 0" xyz="0 0 0"/>
      <geometry>
        <mesh filename="package://ayg_description/meshes/R_Hip.STL"/>
      </geometry>
    </collision>
  </link>
  <joint name="RF_HAA" type="revolute">
    <origin rpy="-1.5708 0 0" xyz="0.197 -0.054 0"/>
    <parent link="Base"/>
    <child link="RF_Hip"/>
    <axis xyz="1 0 0"/>
    <limit effort="50.0" lower="-0.34907" upper="0.5236" velocity="10.0"/>
  </joint>
  <link name="RF_Thigh">
    <inertial>
      <origin rpy="0 0 0" xyz="-0.00815740475775473 -0.0091268940561607 0.0420066354122466"/>
      <mass value="1.15974999242447"/>
      <inertia ixx="0.000911992879285499" ixy="-0.000310524680969909" ixz="4.28891709883383E-15" iyy="0.000918973664621895" iyz="1.93894536662709E-06" izz="0.00169326046595172"/>
    </inertial>
    <visual>
      <origin rpy="0 0 0" xyz="0 0 0"/>
      <geometry>
        <mesh filename="package://ayg_description/meshes/R_Thigh.STL"/>
      </geometry>
      <material name="">
        <color rgba="0.698039215686274 0.698039215686274 0.698039215686274 1"/>
      </material>
    </visual>
    <collision>
      <origin rpy="0 0 0" xyz="0 0 0"/>
      <geometry>
        <mesh filename="package://ayg_description/meshes/R_Thigh.STL"/>
      </geometry>
    </collision>
  </link>
  <joint name="RF_HFE" type="revolute">
    <origin rpy="3.1416 0 0" xyz="0.0665 0 -0.019"/>
    <parent link="RF_Hip"/>
    <child link="RF_Thigh"/>
    <axis xyz="0 0 1"/>
    <limit effort="50.0" lower="-0.87266" upper="2.5307" velocity="10.0"/>
  </joint>
  <link name="RF_Shank">
    <inertial>
      <origin rpy="0 0 0" xyz="0.0630329536265653 -0.047817827674744 0.0185"/>
      <mass value="0.102570008997248"/>
      <inertia ixx="0.000297677648787269" ixy="0.000296980915761884" ixz="1.63489615161778E-19" iyy="0.000327832614532812" iyz="-1.53587053010883E-19" izz="0.000624546801244392"/>
    </inertial>
    <visual>
      <origin rpy="0 0 0" xyz="0 0 0"/>
      <geometry>
        <mesh filename="package://ayg_description/meshes/R_Shank.STL"/>
      </geometry>
      <material name="">
        <color rgba="0.698039215686274 0.698039215686274 0.698039215686274 1"/>
      </material>
    </visual>
    <collision>
      <origin rpy="0 0 0" xyz="0 0 0"/>
      <geometry>
        <mesh filename="package://ayg_description/meshes/R_Shank.STL"/>
      </geometry>
    </collision>
  </link>
  <joint name="RF_KFE" type="revolute">
    <origin rpy="0 0 0" xyz="-0.14936 -0.16017 0.052"/>
    <parent link="RF_Thigh"/>
    <child link="RF_Shank"/>
    <axis xyz="0 0 1"/>
    <limit effort="50.0" lower="-0.7854" upper="1.2217" velocity="10.0"/>
  </joint>
  <link name="RF_Foot">
    <inertial>
      <origin rpy="0 1.5707963267948966 0" xyz="0 0 0"/>
      <mass value="0.088054927521184"/>
      <inertia ixx="4.09565481632907E-05" ixy="-1.1480272825008E-21" ixz="3.01597797886474E-21" iyy="2.47049106026622E-05" iyz="2.27429196641528E-36" izz="2.47049106026622E-05"/>
    </inertial>
    <visual>
      <origin rpy="0 0 0" xyz="0 0 0"/>
      <geometry>
        <cylinder length="0.025" radius="0.030"/>
      </geometry>
      <material name="">
        <color rgba="0.250980392156863 0.250980392156863 0.250980392156863 1"/>
      </material>
    </visual>
    <collision>
      <origin rpy="0 0 0" xyz="0 0 0"/>
      <geometry>
        <cylinder length="0.025" radius="0.030"/>
      </geometry>
    </collision>
  </link>
  <joint name="RF_Shank_2_Foot" type="fixed">
    <origin rpy="0 0 0" xyz="0.165 -0.151 0.0185"/>
    <parent link="RF_Shank"/>
    <child link="RF_Foot"/>
    <axis xyz="0 0 0"/>
  </joint>
  <link name="LH_Hip">
    <inertial>
      <origin rpy="0 0 0" xyz="0.062462530502862 0.000263588472360432 0.0024140975794637"/>
      <mass value="1.00401999005125"/>
      <inertia ixx="0.000584357699669872" ixy="1.71578981310067E-06" ixz="-2.61675027998363E-19" iyy="0.000584539401732687" iyz="-3.57751728713357E-20" izz="0.00102756652010595"/>
    </inertial>
    <visual>
      <origin rpy="0 0 0" xyz="0 0 0"/>
      <geometry>
        <mesh filename="package://ayg_description/meshes/L_Hip.STL"/>
      </geometry>
      <material name="">
        <color rgba="0.698039215686274 0.698039215686274 0.698039215686274 1"/>
      </material>
    </visual>
    <collision>
      <origin rpy="0 0 0" xyz="0 0 0"/>
      <geometry>
        <mesh filename="package://ayg_description/meshes/L_Hip.STL"/>
      </geometry>
    </collision>
  </link>
  <joint name="LH_HAA" type="revolute">
    <origin rpy="-1.5708 0 3.1416" xyz="-0.197 0.054 0"/>
    <parent link="Base"/>
    <child link="LH_Hip"/>
    <axis xyz="1 0 0"/>
    <limit effort="50.0" lower="-0.87266" upper="0.5236" velocity="10.0"/>
  </joint>
  <link name="LH_Thigh">
    <inertial>
      <origin rpy="0 0 0" xyz="-0.00815740476229621 -0.00912689407030123 -0.0420066354122466"/>
      <mass value="1.15974999242447"/>
      <inertia ixx="0.000911992879302287" ixy="-0.000310524680951164" ixz="-4.3266057977693E-16" iyy="0.00091897366461706" iyz="-1.93894477964206E-06" izz="0.00169326046596367"/>
    </inertial>
    <visual>
      <origin rpy="0 0 0" xyz="0 0 0"/>
      <geometry>
        <mesh filename="package://ayg_description/meshes/L_Thigh.STL"/>
      </geometry>
      <material name="">
        <color rgba="0.698039215686274 0.698039215686274 0.698039215686274 1"/>
      </material>
    </visual>
    <collision>
      <origin rpy="0 0 0" xyz="0 0 0"/>
      <geometry>
        <mesh filename="package://ayg_description/meshes/L_Thigh.STL"/>
      </geometry>
    </collision>
  </link>
  <joint name="LH_HFE" type="revolute">
    <origin rpy="0 0 3.1416" xyz="0.0665 0 -0.019"/>
    <parent link="LH_Hip"/>
    <child link="LH_Thigh"/>
    <axis xyz="0 0 1"/>
    <limit effort="50.0" lower="-2.5307" upper="0.87266" velocity="10.0"/>
  </joint>
  <link name="LH_Shank">
    <inertial>
      <origin rpy="0 0 0" xyz="0.0630329536265654 -0.047817827674744 -0.0185"/>
      <mass value="0.102570008997248"/>
      <inertia ixx="0.00029767764878727" ixy="0.000296980915761884" ixz="1.63288326545704E-19" iyy="0.000327832614532812" iyz="-1.54063121876522E-19" izz="0.000624546801244392"/>
    </inertial>
    <visual>
      <origin rpy="0 0 0" xyz="0 0 0"/>
      <geometry>
        <mesh filename="package://ayg_description/meshes/L_Shank.STL"/>
      </geometry>
      <material name="">
        <color rgba="0.698039215686274 0.698039215686274 0.698039215686274 1"/>
      </material>
    </visual>
    <collision>
      <origin rpy="0 0 0" xyz="0 0 0"/>
      <geometry>
        <mesh filename="package://ayg_description/meshes/L_Shank.STL"/>
      </geometry>
    </collision>
  </link>
  <joint name="LH_KFE" type="revolute">
    <origin rpy="0 0 0" xyz="-0.14936 -0.16017 -0.052"/>
    <parent link="LH_Thigh"/>
    <child link="LH_Shank"/>
    <axis xyz="0 0 1"/>
    <limit effort="50.0" lower="-0.7854" upper="1.2217" velocity="10.0"/>
  </joint>
  <link name="LH_Foot">
    <inertial>
      <origin rpy="0 1.5707963267948966 0" xyz="-2.77555756156289E-17 5.55111512312578E-17 0"/>
      <mass value="0.088054927521184"/>
      <inertia ixx="4.09565481632907E-05" ixy="-8.61058027358505E-21" ixz="2.27932697045296E-20" iyy="2.47049106026622E-05" iyz="5.04870979341448E-29" izz="2.47049106026622E-05"/>
    </inertial>
    <visual>
      <origin rpy="0 0 0" xyz="0 0 0"/>
      <geometry>
        <cylinder length="0.025" radius="0.030"/>
      </geometry>
      <material name="">
        <color rgba="0.250980392156863 0.250980392156863 0.250980392156863 1"/>
      </material>
    </visual>
    <collision>
      <origin rpy="0 0 0" xyz="0 0 0"/>
      <geometry>
        <cylinder length="0.025" radius="0.030"/>
      </geometry>
    </collision>
  </link>
  <joint name="LH_Shank_2_Foot" type="fixed">
    <origin rpy="0 0 0" xyz="0.165 -0.151 -0.0185"/>
    <parent link="LH_Shank"/>
    <child link="LH_Foot"/>
    <axis xyz="0 0 0"/>
  </joint>
  <link name="RH_Hip">
    <inertial>
      <origin rpy="0 0 0" xyz="0.0624625305028617 0.000263588472359603 -0.00241409757946362"/>
      <mass value="1.00401999005125"/>
      <inertia ixx="0.000584357699669871" ixy="1.71578981310067E-06" ixz="-3.08533699148142E-19" iyy="0.000584539401732687" iyz="1.3310433650471E-20" izz="0.00102756652010595"/>
    </inertial>
    <visual>
      <origin rpy="0 0 0" xyz="0 0 0"/>
      <geometry>
        <mesh filename="package://ayg_description/meshes/R_Hip.STL"/>
      </geometry>
      <material name="">
        <color rgba="0.698039215686274 0.698039215686274 0.698039215686274 1"/>
      </material>
    </visual>
    <collision>
      <origin rpy="0 0 0" xyz="0 0 0"/>
      <geometry>
        <mesh filename="package://ayg_description/meshes/R_Hip.STL"/>
      </geometry>
    </collision>
  </link>
  <joint name="RH_HAA" type="revolute">
    <origin rpy="-1.5708 0 3.1416" xyz="-0.197 -0.054 0"/>
    <parent link="Base"/>
    <child link="RH_Hip"/>
    <axis xyz="1 0 0"/>
    <limit effort="50.0" lower="-0.5236" upper="0.87266" velocity="10.0"/>
  </joint>
  <link name="RH_Thigh">
    <inertial>
      <origin rpy="0 0 0" xyz="-0.00815740475775473 -0.0091268940561607 0.0420066354122466"/>
      <mass value="1.15974999242447"/>
      <inertia ixx="0.000911992879285499" ixy="-0.000310524680969909" ixz="4.28891709883383E-15" iyy="0.000918973664621895" iyz="1.93894536662709E-06" izz="0.00169326046595172"/>
    </inertial>
    <visual>
      <origin rpy="0 0 0" xyz="0 0 0"/>
      <geometry>
        <mesh filename="package://ayg_description/meshes/R_Thigh.STL"/>
      </geometry>
      <material name="">
        <color rgba="0.698039215686274 0.698039215686274 0.698039215686274 1"/>
      </material>
    </visual>
    <collision>
      <origin rpy="0 0 0" xyz="0 0 0"/>
      <geometry>
        <mesh filename="package://ayg_description/meshes/R_Thigh.STL"/>
      </geometry>
    </collision>
  </link>
  <joint name="RH_HFE" type="revolute">
    <origin rpy="0 0 3.1416" xyz="0.0665 0 0.019"/>
    <parent link="RH_Hip"/>
    <child link="RH_Thigh"/>
    <axis xyz="0 0 1"/>
    <limit effort="50.0" lower="-2.5307" upper="0.87266" velocity="10.0"/>
  </joint>
  <link name="RH_Shank">
    <inertial>
      <origin rpy="0 0 0" xyz="0.0630329536265653 -0.047817827674744 0.0185"/>
      <mass value="0.102570008997248"/>
      <inertia ixx="0.000297677648787269" ixy="0.000296980915761884" ixz="1.63489615161778E-19" iyy="0.000327832614532812" iyz="-1.53587053010883E-19" izz="0.000624546801244392"/>
    </inertial>
    <visual>
      <origin rpy="0 0 0" xyz="0 0 0"/>
      <geometry>
        <mesh filename="package://ayg_description/meshes/R_Shank.STL"/>
      </geometry>
      <material name="">
        <color rgba="0.698039215686274 0.698039215686274 0.698039215686274 1"/>
      </material>
    </visual>
    <collision>
      <origin rpy="0 0 0" xyz="0 0 0"/>
      <geometry>
        <mesh filename="package://ayg_description/meshes/R_Shank.STL"/>
      </geometry>
    </collision>
  </link>
  <joint name="RH_KFE" type="revolute">
    <origin rpy="0 0 0" xyz="-0.14936 -0.16017 0.052"/>
    <parent link="RH_Thigh"/>
    <child link="RH_Shank"/>
    <axis xyz="0 0 1"/>
    <limit effort="50.0" lower="-0.7854" upper="1.2217" velocity="10.0"/>
  </joint>
  <link name="RH_Foot">
    <inertial>
      <origin rpy="0 1.5707963267948966 0" xyz="0 0 0"/>
      <mass value="0.088054927521184"/>
      <inertia ixx="4.09565481632907E-05" ixy="-1.1480272825008E-21" ixz="3.01597797886474E-21" iyy="2.47049106026622E-05" iyz="2.27429196641528E-36" izz="2.47049106026622E-05"/>
    </inertial>
    <visual>
      <origin rpy="0 0 0" xyz="0 0 0"/>
      <geometry>
        <cylinder length="0.025" radius="0.030"/>
      </geometry>
      <material name="">
        <color rgba="0.250980392156863 0.250980392156863 0.250980392156863 1"/>
      </material>
    </visual>
    <collision>
      <origin rpy="0 0 0" xyz="0 0 0"/>
      <geometry>
        <cylinder length="0.025" radius="0.030"/>
      </geometry>
    </collision>
  </link>
  <joint name="RH_Shank_2_Foot" type="fixed">
    <origin rpy="0 0 0" xyz="0.165 -0.151 0.0185"/>
    <parent link="RH_Shank"/>
    <child link="RH_Foot"/>
    <axis xyz="0 0 0"/>
  </joint>
  <link name="IMU">
    <inertial>
      <origin rpy="0 0 0" xyz="-8.67049396793524E-18 0.02 5.37094698008006E-18"/>
      <mass value="0.08"/>
      <inertia ixx="2.13333333333333E-05" ixy="-4.34540023236298E-22" ixz="-1.52363539595465E-21" iyy="2.73333333333333E-05" iyz="-2.43977500178881E-21" izz="2.73333333333333E-05"/>
    </inertial>
    <visual>
      <origin rpy="0 0 0" xyz="0 0 0"/>
      <geometry>
        <mesh filename="package://ayg_description/meshes/IMU.STL"/>
      </geometry>
      <material name="">
        <color rgba="0.792156862745098 0.819607843137255 0.933333333333333 1"/>
      </material>
    </visual>
  </link>
  <joint name="Base_2_IMU" type="fixed">
    <origin rpy="-1.5708 0 1.5708" xyz="0 0 0.006"/>
    <parent link="Base"/>
    <child link="IMU"/>
    <axis xyz="0 0 0"/>
  </joint>
  <link name="Neck">
    <inertial>
      <origin rpy="0 0 0" xyz="0 0 0"/>
      <mass value="0"/>
      <inertia ixx="0" ixy="0" ixz="0" iyy="0" iyz="0" izz="0"/>
    </inertial>
    <visual>
      <origin rpy="0 0 0" xyz="0 0 0"/>
      <geometry>
        <mesh filename="package://ayg_description/meshes/Neck.STL"/>
      </geometry>
      <material name="">
        <color rgba="1 1 1 1"/>
      </material>
    </visual>
    <collision>
      <origin rpy="0 0 0" xyz="0 0 0"/>
      <geometry>
        <mesh filename="package://ayg_description/meshes/Neck.STL"/>
      </geometry>
    </collision>
  </link>
  <joint name="Base_2_Neck" type="fixed">
    <origin rpy="1.5707963267949 0 1.5707963267949" xyz="0.2615 0 0.0249999999999999"/>
    <parent link="Base"/>
    <child link="Neck"/>
    <axis xyz="0 0 0"/>
  </joint>
  <link name="Camera">
    <inertial>
      <origin rpy="0 0 0" xyz="7.0525E-18 -2.7756E-17 0.013"/>
      <mass value="0.16948"/>
      <inertia ixx="2.085E-05" ixy="5.6809E-20" ixz="-7.2863E-20" iyy="0.00020719" iyz="3.3881E-21" izz="0.00020895"/>
    </inertial>
    <visual>
      <origin rpy="0 0 0" xyz="0 0 0"/>
      <geometry>
        <mesh filename="package://ayg_description/meshes/Camera.STL"/>
      </geometry>
      <material name="">
        <color rgba="0.25098 0.25098 0.25098 1"/>
      </material>
    </visual>
    <collision>
      <origin rpy="0 0 0" xyz="0 0 0"/>
      <geometry>
        <mesh filename="package://ayg_description/meshes/Camera.STL"/>
      </geometry>
    </collision>
  </link>
  <joint name="Neck_2_Camera" type="fixed">
    <origin rpy="0.288975409992567 0 0" xyz="0 0.0166603444360147 0.0804068913666247"/>
    <parent link="Neck"/>
    <child link="Camera"/>
    <axis xyz="0 0 0"/>
  </joint>
</robot>
