<?xml version="1.0" ?>
<!-- =================================================================================== -->
<!-- |    This document was autogenerated by xacro from src/ayg_description/urdf/ayg.xacro | -->
<!-- |    EDITING THIS FILE BY HAND IS NOT RECOMMENDED                                 | -->
<!-- =================================================================================== -->
<robot name="ayg">
  <!-- Robstride ros2_control macro for quadruped -->
  <!-- Include this in your main robot URDF to add hardware interface -->
  <ros2_control name="RobstrideSystem" type="system">
    <hardware>
      <plugin>robstride_hardware/RobstrideSystem</plugin>
      <param name="actuator_type">3</param>
      <param name="default_kp">40.0</param>
      <param name="default_kd">1.0</param>
      <param name="calibration_file">/home/ayg/ayg_ws/install/robstride_hardware/share/robstride_hardware/calibration/joint_calibration.yaml</param>
    </hardware>
    <joint name="LF_HAA">
      <param name="can_id">1</param>
      <param name="can_interface">can0</param>
      <param name="position_min">-0.5236</param>
      <param name="position_max">0.436</param>
      <command_interface name="position"/>
      <command_interface name="velocity"/>
      <command_interface name="effort"/>
      <command_interface name="kp"/>
      <command_interface name="kd"/>
      <state_interface name="position"/>
      <state_interface name="velocity"/>
      <state_interface name="effort"/>
      <state_interface name="temperature"/>
    </joint>
    <joint name="LF_HFE">
      <param name="can_id">2</param>
      <param name="can_interface">can0</param>
      <param name="position_min">-1.667</param>
      <param name="position_max">3.238</param>
      <command_interface name="position"/>
      <command_interface name="velocity"/>
      <command_interface name="effort"/>
      <command_interface name="kp"/>
      <command_interface name="kd"/>
      <state_interface name="position"/>
      <state_interface name="velocity"/>
      <state_interface name="effort"/>
      <state_interface name="temperature"/>
    </joint>
    <joint name="LF_KFE">
      <param name="can_id">3</param>
      <param name="can_interface">can0</param>
      <param name="position_min">-0.74</param>
      <param name="position_max">1.187</param>
      <command_interface name="position"/>
      <command_interface name="velocity"/>
      <command_interface name="effort"/>
      <command_interface name="kp"/>
      <command_interface name="kd"/>
      <state_interface name="position"/>
      <state_interface name="velocity"/>
      <state_interface name="effort"/>
      <state_interface name="temperature"/>
    </joint>
    <joint name="RF_HAA">
      <param name="can_id">4</param>
      <param name="can_interface">can1</param>
      <param name="position_min">-0.4363</param>
      <param name="position_max">0.5236</param>
      <command_interface name="position"/>
      <command_interface name="velocity"/>
      <command_interface name="effort"/>
      <command_interface name="kp"/>
      <command_interface name="kd"/>
      <state_interface name="position"/>
      <state_interface name="velocity"/>
      <state_interface name="effort"/>
      <state_interface name="temperature"/>
    </joint>
    <joint name="RF_HFE">
      <param name="can_id">5</param>
      <param name="can_interface">can1</param>
      <param name="position_min">-1.667</param>
      <param name="position_max">3.238</param>
      <command_interface name="position"/>
      <command_interface name="velocity"/>
      <command_interface name="effort"/>
      <command_interface name="kp"/>
      <command_interface name="kd"/>
      <state_interface name="position"/>
      <state_interface name="velocity"/>
      <state_interface name="effort"/>
      <state_interface name="temperature"/>
    </joint>
    <joint name="RF_KFE">
      <param name="can_id">6</param>
      <param name="can_interface">can1</param>
      <param name="position_min">-0.74</param>
      <param name="position_max">1.187</param>
      <command_interface name="position"/>
      <command_interface name="velocity"/>
      <command_interface name="effort"/>
      <command_interface name="kp"/>
      <command_interface name="kd"/>
      <state_interface name="position"/>
      <state_interface name="velocity"/>
      <state_interface name="effort"/>
      <state_interface name="temperature"/>
    </joint>
    <joint name="LH_HAA">
      <param name="can_id">7</param>
      <param name="can_interface">can2</param>
      <param name="position_min">-0.5236</param>
      <param name="position_max">0.8378</param>
      <command_interface name="position"/>
      <command_interface name="velocity"/>
      <command_interface name="effort"/>
      <command_interface name="kp"/>
      <command_interface name="kd"/>
      <state_interface name="position"/>
      <state_interface name="velocity"/>
      <state_interface name="effort"/>
      <state_interface name="temperature"/>
    </joint>
    <joint name="LH_HFE">
      <param name="can_id">8</param>
      <param name="can_interface">can2</param>
      <param name="position_min">-2.4522</param>
      <param name="position_max">2.4522</param>
      <command_interface name="position"/>
      <command_interface name="velocity"/>
      <command_interface name="effort"/>
      <command_interface name="kp"/>
      <command_interface name="kd"/>
      <state_interface name="position"/>
      <state_interface name="velocity"/>
      <state_interface name="effort"/>
      <state_interface name="temperature"/>
    </joint>
    <joint name="LH_KFE">
      <param name="can_id">9</param>
      <param name="can_interface">can2</param>
      <param name="position_min">-0.74</param>
      <param name="position_max">1.187</param>
      <command_interface name="position"/>
      <command_interface name="velocity"/>
      <command_interface name="effort"/>
      <command_interface name="kp"/>
      <command_interface name="kd"/>
      <state_interface name="position"/>
      <state_interface name="velocity"/>
      <state_interface name="effort"/>
      <state_interface name="temperature"/>
    </joint>
    <joint name="RH_HAA">
      <param name="can_id">10</param>
      <param name="can_interface">can3</param>
      <param name="position_min">-0.8378</param>
      <param name="position_max">0.5236</param>
      <command_interface name="position"/>
      <command_interface name="velocity"/>
      <command_interface name="effort"/>
      <command_interface name="kp"/>
      <command_interface name="kd"/>
      <state_interface name="position"/>
      <state_interface name="velocity"/>
      <state_interface name="effort"/>
      <state_interface name="temperature"/>
    </joint>
    <joint name="RH_HFE">
      <param name="can_id">11</param>
      <param name="can_interface">can3</param>
      <param name="position_min">-2.4522</param>
      <param name="position_max">2.4522</param>
      <command_interface name="position"/>
      <command_interface name="velocity"/>
      <command_interface name="effort"/>
      <command_interface name="kp"/>
      <command_interface name="kd"/>
      <state_interface name="position"/>
      <state_interface name="velocity"/>
      <state_interface name="effort"/>
      <state_interface name="temperature"/>
    </joint>
    <joint name="RH_KFE">
      <param name="can_id">12</param>
      <param name="can_interface">can3</param>
      <param name="position_min">-0.74</param>
      <param name="position_max">1.187</param>
      <command_interface name="position"/>
      <command_interface name="velocity"/>
      <command_interface name="effort"/>
      <command_interface name="kp"/>
      <command_interface name="kd"/>
      <state_interface name="position"/>
      <state_interface name="velocity"/>
      <state_interface name="effort"/>
      <state_interface name="temperature"/>
    </joint>
  </ros2_control>
  <link name="Base">
    <inertial>
      <origin rpy="0 0 0" xyz="0.00057686 -0.00018498 0.0026529"/>
      <!-- Measured: 9.148 kg (CAD: 9.1298 kg) -->
      <mass value="9.148"/>
      <inertia ixx="0.022082" ixy="3.2369E-07" ixz="6.8653E-05" iyy="0.031986" iyz="2.8565E-07" izz="0.040389"/>
    </inertial>
    <visual>
      <origin rpy="0 0 0" xyz="0 0 0"/>
      <geometry>
        <mesh filename="package://ayg_description/meshes/Base.STL"/>
      </geometry>
      <material name="">
        <color rgba="0.69804 0.69804 0.69804 1"/>
      </material>
    </visual>
    <collision>
      <origin rpy="0 0 0" xyz="0 0 0"/>
      <geometry>
        <box size="0.4 0.23 0.12"/>
      </geometry>
    </collision>
  </link>
  <link name="IMU">
    <inertial>
      <origin rpy="0 0 0" xyz="-1.26817788945405E-05 -3.05893593341006E-06 0.00502425421604302"/>
      <mass value="0.0181381899874512"/>
      <inertia ixx="4.80017459218422E-06" ixy="-6.17315963282016E-11" ixz="-1.66852937330168E-09" iyy="3.40477341509462E-06" iyz="-3.279931989329E-11" izz="7.92679226862755E-06"/>
    </inertial>
    <visual>
      <origin rpy="0 0 0" xyz="0 0 0"/>
      <geometry>
        <mesh filename="package://ayg_description/meshes/IMU.STL"/>
      </geometry>
      <material name="">
        <color rgba="0.792156862745098 0.819607843137255 0.933333333333333 1"/>
      </material>
    </visual>
  </link>
  <joint name="Base_2_IMU" type="fixed">
    <origin rpy="0 0 0" xyz="-3.79309829856879E-05 0 -0.0172341687059438"/>
    <parent link="Base"/>
    <child link="IMU"/>
    <axis xyz="0 0 0"/>
  </joint>
  <link name="Battery_Front">
    <inertial>
      <origin rpy="0 0 0" xyz="-2e-05 -0.00421 0.04143"/>
      <mass value="1.6"/>
      <inertia ixx="0.004457646056810788" ixy="-4.1872733012492184e-06" ixz="-5.2038629789262776e-06" iyy="0.007677060837408274" iyz="-0.00026672140293911104" izz="0.004447939903489953"/>
    </inertial>
    <visual>
      <origin rpy="0 0 0" xyz="0 0 0"/>
      <geometry>
        <box size="0.079 0.177 0.096"/>
      </geometry>
      <material name="battery_color">
        <color rgba="0.2 0.2 0.3 1"/>
      </material>
    </visual>
    <collision>
      <origin rpy="0 0 0" xyz="0 0 0"/>
      <geometry>
        <box size="0.079 0.177 0.096"/>
      </geometry>
    </collision>
  </link>
  <joint name="Base_2_Battery_Front" type="fixed">
    <origin rpy="0 0 0" xyz="0.1007 0 -0.009"/>
    <parent link="Base"/>
    <child link="Battery_Front"/>
    <axis xyz="0 0 0"/>
  </joint>
  <link name="Battery_Rear">
    <inertial>
      <origin rpy="0 0 0" xyz="-2e-05 -0.00421 0.04143"/>
      <mass value="1.6"/>
      <inertia ixx="0.004457646056810788" ixy="-4.1872733012492184e-06" ixz="-5.2038629789262776e-06" iyy="0.007677060837408274" iyz="-0.00026672140293911104" izz="0.004447939903489953"/>
    </inertial>
    <visual>
      <origin rpy="0 0 0" xyz="0 0 0"/>
      <geometry>
        <box size="0.079 0.177 0.096"/>
      </geometry>
      <material name="battery_color">
        <color rgba="0.2 0.2 0.3 1"/>
      </material>
    </visual>
    <collision>
      <origin rpy="0 0 0" xyz="0 0 0"/>
      <geometry>
        <box size="0.079 0.177 0.096"/>
      </geometry>
    </collision>
  </link>
  <joint name="Base_2_Battery_Rear" type="fixed">
    <origin rpy="0 0 0" xyz="-0.1007 0 -0.009"/>
    <parent link="Base"/>
    <child link="Battery_Rear"/>
    <axis xyz="0 0 0"/>
  </joint>
  <link name="LF_Hip">
    <inertial>
      <origin rpy="0 0 0" xyz="0.063065 -0.0051556 -5.3332E-05"/>
      <mass value="1.0709"/>
      <inertia ixx="0.00078713" ixy="-7.2738E-08" ixz="-1.6354E-06" iyy="0.0013471" iyz="-2.2108E-07" izz="0.00073074"/>
    </inertial>
    <visual>
      <origin rpy="0 0 0" xyz="0 0 0"/>
      <geometry>
        <mesh filename="package://ayg_description/meshes/L_Hip.STL"/>
      </geometry>
      <material name="">
        <color rgba="0.69804 0.69804 0.69804 1"/>
      </material>
    </visual>
    <collision>
      <origin rpy="1.5707963267948966 0 0" xyz="0.0665 0.04 0"/>
      <geometry>
        <cylinder length="0.148" radius="0.05"/>
      </geometry>
    </collision>
  </link>
  <joint name="LF_HAA" type="revolute">
    <origin rpy="0 0 0" xyz="0.2021 0.054 0"/>
    <parent link="Base"/>
    <child link="LF_Hip"/>
    <axis xyz="1 0 0"/>
    <limit effort="50.0" lower="-0.5236" upper="0.43633" velocity="10.0"/>
  </joint>
  <link name="LF_Thigh">
    <inertial>
      <origin rpy="0 0 0" xyz="-0.0095261 0.047418 -0.010869"/>
      <mass value="1.361"/>
      <inertia ixx="0.0012156" ixy="1.025E-06" ixz="-0.00042254" iyy="0.0022368" iyz="-1.3825E-06" izz="0.0012227"/>
    </inertial>
    <visual>
      <origin rpy="0 0 0" xyz="0 0 0"/>
      <geometry>
        <mesh filename="package://ayg_description/meshes/L_Thigh.STL"/>
      </geometry>
      <material name="">
        <color rgba="0.69804 0.69804 0.69804 1"/>
      </material>
    </visual>
    <collision>
      <origin rpy="0.7853981633974483 0 1.5707963267948966" xyz="-0.0975 +0.08 -0.07"/>
      <geometry>
        <box size="0.025 0.05 0.14"/>
      </geometry>
    </collision>
  </link>
  <joint name="LF_HFE" type="revolute">
    <origin rpy="0 0 0" xyz="0.0679 0.01985 0"/>
    <parent link="LF_Hip"/>
    <child link="LF_Thigh"/>
    <axis xyz="0 -1 0"/>
    <limit effort="50.0" lower="-1.6668" upper="3.2376" velocity="10.0"/>
  </joint>
  <link name="LF_Shank">
    <inertial>
      <origin rpy="0 0 0" xyz="0.059297 0.0205 -0.044894"/>
      <mass value="0.19753"/>
      <inertia ixx="0.00059399" ixy="-3.3081E-19" ixz="0.00058611" iyy="0.0012346" iyz="3.1645E-19" izz="0.00065333"/>
    </inertial>
    <visual>
      <origin rpy="0 0 0" xyz="0 0 0"/>
      <geometry>
        <mesh filename="package://ayg_description/meshes/L_Shank.STL"/>
      </geometry>
      <material name="">
        <color rgba="0.69804 0.69804 0.69804 1"/>
      </material>
    </visual>
    <collision>
      <origin rpy="1.5707963267948966 0 0" xyz="0 0.02 0"/>
      <geometry>
        <cylinder length="0.03" radius="0.025"/>
      </geometry>
    </collision>
    <collision>
      <origin rpy="1.5707963267948966 -0.7853981633974483 0" xyz="0.08 0.02 -0.075"/>
      <geometry>
        <box size="0.025 0.165 0.0125"/>
      </geometry>
    </collision>
  </link>
  <joint name="LF_KFE" type="revolute">
    <origin rpy="0 0 0" xyz="-0.14936 0.058 -0.16017"/>
    <parent link="LF_Thigh"/>
    <child link="LF_Shank"/>
    <axis xyz="0 -1 0"/>
    <limit effort="50.0" lower="-0.74002" upper="1.1868" velocity="10.0"/>
  </joint>
  <link name="LF_Foot">
    <inertial>
      <origin rpy="0 0 0" xyz="-2.77555756156289E-17 5.55111512312578E-17 0"/>
      <mass value="0.0701295110066971"/>
      <inertia ixx="1.91783738418569E-05" ixy="4.42768620674145E-20" ixz="8.0334719824878E-35" iyy="3.14806687325575E-05" iyz="2.23148962310519E-20" izz="1.91783738418569E-05"/>
    </inertial>
    <visual>
      <origin rpy="1.5707963267948966 0 0" xyz="0 0 0"/>
      <geometry>
        <cylinder length="0.025" radius="0.030"/>
      </geometry>
      <material name="">
        <color rgba="0.29804 0.29804 0.29804 1"/>
      </material>
    </visual>
    <collision>
      <origin rpy="1.5707963267948966 0 0" xyz="0 0 0"/>
      <geometry>
        <sphere radius="0.030"/>
      </geometry>
    </collision>
  </link>
  <joint name="LF_Shank_2_Foot" type="fixed">
    <origin rpy="0 0 0" xyz="0.165 0.0205 -0.151"/>
    <parent link="LF_Shank"/>
    <child link="LF_Foot"/>
    <axis xyz="0 0 0"/>
  </joint>
  <link name="RF_Hip">
    <inertial>
      <origin rpy="0 0 0" xyz="0.063077 0.0051556 -6.5344E-05"/>
      <mass value="1.071"/>
      <inertia ixx="0.00078713" ixy="7.2742E-08" ixz="-1.6354E-06" iyy="0.0013471" iyz="2.2108E-07" izz="0.00073074"/>
    </inertial>
    <visual>
      <origin rpy="0 0 0" xyz="0 0 0"/>
      <geometry>
        <mesh filename="package://ayg_description/meshes/R_Hip.STL"/>
      </geometry>
      <material name="">
        <color rgba="0.69804 0.69804 0.69804 1"/>
      </material>
    </visual>
    <collision>
      <origin rpy="1.5707963267948966 0 0" xyz="0.0665 -0.04 0"/>
      <geometry>
        <cylinder length="0.148" radius="0.05"/>
      </geometry>
    </collision>
  </link>
  <joint name="RF_HAA" type="revolute">
    <origin rpy="0 0 0" xyz="0.2021 -0.054 0"/>
    <parent link="Base"/>
    <child link="RF_Hip"/>
    <axis xyz="1 0 0"/>
    <limit effort="50.0" lower="-0.43633" upper="0.5236" velocity="10.0"/>
  </joint>
  <link name="RF_Thigh">
    <inertial>
      <origin rpy="0 0 0" xyz="-0.0090964 -0.047418 -0.010862"/>
      <mass value="1.361"/>
      <inertia ixx="0.0012156" ixy="-1.025E-06" ixz="-0.00041957" iyy="0.0022368" iyz="1.3825E-06" izz="0.0012226"/>
    </inertial>
    <visual>
      <origin rpy="0 0 0" xyz="0 0 0"/>
      <geometry>
        <mesh filename="package://ayg_description/meshes/R_Thigh.STL"/>
      </geometry>
      <material name="">
        <color rgba="0.69804 0.69804 0.69804 1"/>
      </material>
    </visual>
    <collision>
      <origin rpy="0.7853981633974483 0 1.5707963267948966" xyz="-0.0975 -0.08 -0.07"/>
      <geometry>
        <box size="0.025 0.05 0.14"/>
      </geometry>
    </collision>
  </link>
  <joint name="RF_HFE" type="revolute">
    <origin rpy="0 0 0" xyz="0.0679 -0.01985 0"/>
    <parent link="RF_Hip"/>
    <child link="RF_Thigh"/>
    <axis xyz="0 -1 0"/>
    <limit effort="50.0" lower="-1.6668" upper="3.2376" velocity="10.0"/>
  </joint>
  <link name="RF_Shank">
    <inertial>
      <origin rpy="0 0 0" xyz="0.059297 -0.0205 -0.044894"/>
      <mass value="0.19753"/>
      <inertia ixx="0.00059399" ixy="-3.307E-19" ixz="0.00058611" iyy="0.0012346" iyz="3.1617E-19" izz="0.00065333"/>
    </inertial>
    <visual>
      <origin rpy="0 0 0" xyz="0 0 0"/>
      <geometry>
        <mesh filename="package://ayg_description/meshes/R_Shank.STL"/>
      </geometry>
      <material name="">
        <color rgba="0.69804 0.69804 0.69804 1"/>
      </material>
    </visual>
    <collision>
      <origin rpy="1.5707963267948966 0 0" xyz="0 -0.02 0"/>
      <geometry>
        <cylinder length="0.03" radius="0.025"/>
      </geometry>
    </collision>
    <collision>
      <origin rpy="1.5707963267948966 -0.7853981633974483 0" xyz="0.08 -0.02 -0.075"/>
      <geometry>
        <box size="0.025 0.165 0.0125"/>
      </geometry>
    </collision>
  </link>
  <joint name="RF_KFE" type="revolute">
    <origin rpy="0 0 0" xyz="-0.14936 -0.058 -0.16017"/>
    <parent link="RF_Thigh"/>
    <child link="RF_Shank"/>
    <axis xyz="0 -1 0"/>
    <limit effort="50.0" lower="-0.74002" upper="1.1868" velocity="10.0"/>
  </joint>
  <link name="RF_Foot">
    <inertial>
      <origin rpy="0 0 0" xyz="0 0 0"/>
      <mass value="0.07013"/>
      <inertia ixx="1.9178E-05" ixy="-3.5293E-22" ixz="2.1771E-38" iyy="3.1481E-05" iyz="3.5306E-38" izz="1.9178E-05"/>
    </inertial>
    <visual>
      <origin rpy="1.5707963267948966 0 0" xyz="0 0 0"/>
      <geometry>
        <cylinder length="0.025" radius="0.030"/>
      </geometry>
      <material name="">
        <color rgba="0.29804 0.29804 0.29804 1"/>
      </material>
    </visual>
    <collision>
      <origin rpy="1.5707963267948966 0 0" xyz="0 0 0"/>
      <geometry>
        <sphere radius="0.030"/>
      </geometry>
    </collision>
  </link>
  <joint name="RF_Shank_2_Foot" type="fixed">
    <origin rpy="0 0 0" xyz="0.165 -0.0205 -0.151"/>
    <parent link="RF_Shank"/>
    <child link="RF_Foot"/>
    <axis xyz="0 0 0"/>
  </joint>
  <link name="LH_Hip">
    <inertial>
      <origin rpy="0 0 0" xyz="0.063077 0.0051556 -6.5344E-05"/>
      <mass value="1.0709"/>
      <inertia ixx="0.00078713" ixy="-7.2738E-08" ixz="-1.6354E-06" iyy="0.0013471" iyz="-2.2108E-07" izz="0.00073074"/>
    </inertial>
    <visual>
      <origin rpy="0 0 0" xyz="0 0 0"/>
      <geometry>
        <mesh filename="package://ayg_description/meshes/R_Hip.STL"/>
      </geometry>
      <material name="">
        <color rgba="0.69804 0.69804 0.69804 1"/>
      </material>
    </visual>
    <collision>
      <origin rpy="1.5707963267948966 0 0" xyz="0.0665 -0.04 0"/>
      <geometry>
        <cylinder length="0.148" radius="0.05"/>
      </geometry>
    </collision>
  </link>
  <joint name="LH_HAA" type="revolute">
    <origin rpy="0 0 3.1416" xyz="-0.2021 0.054 0"/>
    <parent link="Base"/>
    <child link="LH_Hip"/>
    <axis xyz="-1 0 0"/>
    <limit effort="50.0" lower="-0.5236" upper="0.83776" velocity="10.0"/>
  </joint>
  <link name="LH_Thigh">
    <inertial>
      <origin rpy="0 0 0" xyz="-0.0095261 0.047418 -0.010869"/>
      <mass value="1.361"/>
      <inertia ixx="0.0012156" ixy="1.025E-06" ixz="-0.00042254" iyy="0.0022368" iyz="-1.3825E-06" izz="0.0012227"/>
    </inertial>
    <visual>
      <origin rpy="0 0 0" xyz="0 0 0"/>
      <geometry>
        <mesh filename="package://ayg_description/meshes/L_Thigh.STL"/>
      </geometry>
      <material name="">
        <color rgba="0.69804 0.69804 0.69804 1"/>
      </material>
    </visual>
    <collision>
      <origin rpy="0.7853981633974483 0 1.5707963267948966" xyz="-0.0975 +0.08 -0.07"/>
      <geometry>
        <box size="0.025 0.05 0.14"/>
      </geometry>
    </collision>
  </link>
  <joint name="LH_HFE" type="revolute">
    <origin rpy="0 0 3.1416" xyz="0.0679 -0.01985 0"/>
    <parent link="LH_Hip"/>
    <child link="LH_Thigh"/>
    <axis xyz="0 -1 0"/>
    <limit effort="50.0" lower="-2.4522" upper="2.4522" velocity="10.0"/>
  </joint>
  <link name="LH_Shank">
    <inertial>
      <origin rpy="0 0 0" xyz="0.059297 0.0205 -0.044894"/>
      <mass value="0.19753"/>
      <inertia ixx="0.00059399" ixy="-3.3081E-19" ixz="0.00058611" iyy="0.0012346" iyz="3.1645E-19" izz="0.00065333"/>
    </inertial>
    <visual>
      <origin rpy="0 0 0" xyz="0 0 0"/>
      <geometry>
        <mesh filename="package://ayg_description/meshes/L_Shank.STL"/>
      </geometry>
      <material name="">
        <color rgba="0.69804 0.69804 0.69804 1"/>
      </material>
    </visual>
    <collision>
      <origin rpy="1.5707963267948966 0 0" xyz="0 0.02 0"/>
      <geometry>
        <cylinder length="0.03" radius="0.025"/>
      </geometry>
    </collision>
    <collision>
      <origin rpy="1.5707963267948966 -0.7853981633974483 0" xyz="0.08 0.02 -0.075"/>
      <geometry>
        <box size="0.025 0.165 0.0125"/>
      </geometry>
    </collision>
  </link>
  <joint name="LH_KFE" type="revolute">
    <origin rpy="0 0 0" xyz="-0.14936 0.058 -0.16017"/>
    <parent link="LH_Thigh"/>
    <child link="LH_Shank"/>
    <axis xyz="0 -1 0"/>
    <limit effort="50.0" lower="-0.74002" upper="1.1868" velocity="10.0"/>
  </joint>
  <link name="LH_Foot">
    <inertial>
      <origin rpy="0 0 0" xyz="-2.77555756156289E-17 5.55111512312578E-17 0"/>
      <mass value="0.0701295110066971"/>
      <inertia ixx="1.91783738418569E-05" ixy="4.42768620674145E-20" ixz="8.0334719824878E-35" iyy="3.14806687325575E-05" iyz="2.23148962310519E-20" izz="1.91783738418569E-05"/>
    </inertial>
    <visual>
      <origin rpy="1.5707963267948966 0 0" xyz="0 0 0"/>
      <geometry>
        <cylinder length="0.025" radius="0.030"/>
      </geometry>
      <material name="">
        <color rgba="0.29804 0.29804 0.29804 1"/>
      </material>
    </visual>
    <collision>
      <origin rpy="1.5707963267948966 0 0" xyz="0 0 0"/>
      <geometry>
        <sphere radius="0.030"/>
      </geometry>
    </collision>
  </link>
  <joint name="LH_Shank_2_Foot" type="fixed">
    <origin rpy="0 0 0" xyz="0.165 0.0205 -0.151"/>
    <parent link="LH_Shank"/>
    <child link="LH_Foot"/>
    <axis xyz="0 0 0"/>
  </joint>
  <link name="RH_Hip">
    <inertial>
      <origin rpy="0 0 0" xyz="-0.063065 0.0051556 -5.3332E-05"/>
      <mass value="1.071"/>
      <inertia ixx="0.00078713" ixy="7.2742E-08" ixz="-1.6354E-06" iyy="0.0013471" iyz="2.2108E-07" izz="0.00073074"/>
    </inertial>
    <visual>
      <origin rpy="0 0 0" xyz="0 0 0"/>
      <geometry>
        <mesh filename="package://ayg_description/meshes/L_Hip.STL"/>
      </geometry>
      <material name="">
        <color rgba="0.69804 0.69804 0.69804 1"/>
      </material>
    </visual>
    <collision>
      <origin rpy="1.5707963267948966 0 0" xyz="0.0665 0.04 0"/>
      <geometry>
        <cylinder length="0.148" radius="0.05"/>
      </geometry>
    </collision>
  </link>
  <joint name="RH_HAA" type="revolute">
    <origin rpy="0 0 3.1416" xyz="-0.2021 -0.054 0"/>
    <parent link="Base"/>
    <child link="RH_Hip"/>
    <axis xyz="-1 0 0"/>
    <limit effort="50.0" lower="-0.83776" upper="0.5236" velocity="10.0"/>
  </joint>
  <link name="RH_Thigh">
    <inertial>
      <origin rpy="0 0 0" xyz="-0.0090964 -0.047418 -0.010862"/>
      <mass value="1.361"/>
      <inertia ixx="0.0012156" ixy="-1.025E-06" ixz="-0.00041957" iyy="0.0022368" iyz="1.3825E-06" izz="0.0012226"/>
    </inertial>
    <visual>
      <origin rpy="0 0 0" xyz="0 0 0"/>
      <geometry>
        <mesh filename="package://ayg_description/meshes/R_Thigh.STL"/>
      </geometry>
      <material name="">
        <color rgba="0.69804 0.69804 0.69804 1"/>
      </material>
    </visual>
    <collision>
      <origin rpy="0.7853981633974483 0 1.5707963267948966" xyz="-0.0975 -0.08 -0.07"/>
      <geometry>
        <box size="0.025 0.05 0.14"/>
      </geometry>
    </collision>
  </link>
  <joint name="RH_HFE" type="revolute">
    <origin rpy="0 0 3.1416" xyz="0.0665 0.01985 0"/>
    <parent link="RH_Hip"/>
    <child link="RH_Thigh"/>
    <axis xyz="0 -1 0"/>
    <limit effort="50.0" lower="-2.4522" upper="2.4522" velocity="10.0"/>
  </joint>
  <link name="RH_Shank">
    <inertial>
      <origin rpy="0 0 0" xyz="0.059297 -0.0205 -0.044894"/>
      <mass value="0.19753"/>
      <inertia ixx="0.00059399" ixy="-3.307E-19" ixz="0.00058611" iyy="0.0012346" iyz="3.1617E-19" izz="0.00065333"/>
    </inertial>
    <visual>
      <origin rpy="0 0 0" xyz="0 0 0"/>
      <geometry>
        <mesh filename="package://ayg_description/meshes/R_Shank.STL"/>
      </geometry>
      <material name="">
        <color rgba="0.69804 0.69804 0.69804 1"/>
      </material>
    </visual>
    <collision>
      <origin rpy="1.5707963267948966 0 0" xyz="0 -0.02 0"/>
      <geometry>
        <cylinder length="0.03" radius="0.025"/>
      </geometry>
    </collision>
    <collision>
      <origin rpy="1.5707963267948966 -0.7853981633974483 0" xyz="0.08 -0.02 -0.075"/>
      <geometry>
        <box size="0.025 0.165 0.0125"/>
      </geometry>
    </collision>
  </link>
  <joint name="RH_KFE" type="revolute">
    <origin rpy="0 0 0" xyz="-0.14936 -0.058 -0.16017"/>
    <parent link="RH_Thigh"/>
    <child link="RH_Shank"/>
    <axis xyz="0 -1 0"/>
    <limit effort="50.0" lower="-0.74002" upper="1.1868" velocity="10.0"/>
  </joint>
  <link name="RH_Foot">
    <inertial>
      <origin rpy="0 0 0" xyz="0 0 0"/>
      <mass value="0.07013"/>
      <inertia ixx="1.9178E-05" ixy="-3.5293E-22" ixz="2.1771E-38" iyy="3.1481E-05" iyz="3.5306E-38" izz="1.9178E-05"/>
    </inertial>
    <visual>
      <origin rpy="1.5707963267948966 0 0" xyz="0 0 0"/>
      <geometry>
        <cylinder length="0.025" radius="0.030"/>
      </geometry>
      <material name="">
        <color rgba="0.29804 0.29804 0.29804 1"/>
      </material>
    </visual>
    <collision>
      <origin rpy="1.5707963267948966 0 0" xyz="0 0 0"/>
      <geometry>
        <sphere radius="0.030"/>
      </geometry>
    </collision>
  </link>
  <joint name="RH_Shank_2_Foot" type="fixed">
    <origin rpy="0 0 0" xyz="0.165 -0.0205 -0.151"/>
    <parent link="RH_Shank"/>
    <child link="RH_Foot"/>
    <axis xyz="0 0 0"/>
  </joint>
  <!-- Physical Camera body (mesh + inertials from SolidWorks export). -->
  <link name="Camera">
    <inertial>
      <origin rpy="0 0 0" xyz="0.027539 -0.0054988 -1.4524E-08"/>
      <mass value="0.3912"/>
      <inertia ixx="0.00080723" ixy="4.4453E-06" ixz="-1.7833E-09" iyy="0.00082275" iyz="2.4795E-09" izz="0.00010329"/>
    </inertial>
    <visual>
      <origin rpy="0 0 0" xyz="0 0 0"/>
      <geometry>
        <mesh filename="package://ayg_description/meshes/Camera.STL"/>
      </geometry>
      <material name="">
        <color rgba="0.69804 0.69804 0.69804 1"/>
      </material>
    </visual>
    <!--
      Collision simplified from the full Camera.STL to a primitive box sized
      to the bare D555 housing (mesh housing extent 0.0571 x 0.0443 x 0.1670 m,
      centered at 0.0286 -0.0070 0 in the Camera link frame). The thin rear
      mounting tab (-0.035 m in X) is intentionally excluded. A box is far
      cheaper for the physics broadphase/narrowphase than a 1978-triangle mesh.
    -->
    <collision>
      <origin rpy="0 0 0" xyz="0.0286 -0.007 0"/>
      <geometry>
        <box size="0.0571 0.0443 0.167"/>
      </geometry>
    </collision>
  </link>
  <joint name="Base_2_Camera" type="fixed">
    <origin rpy="1.5708 0 0" xyz="0.2475 0 0.095"/>
    <parent link="Base"/>
    <child link="Camera"/>
    <axis xyz="0 0 0"/>
  </joint>
  <link name="Camera_depth_frame">
    <inertial>
      <origin rpy="0 0 0" xyz="0 0 0"/>
      <mass value="1e-6"/>
      <inertia ixx="1e-9" ixy="0" ixz="0" iyy="1e-9" iyz="0" izz="1e-9"/>
    </inertial>
  </link>
  <joint name="Camera_depth_joint" type="fixed">
    <origin rpy="-1.5707963267948966 0 0" xyz="0.0527 -0.024 0"/>
    <parent link="Camera"/>
    <child link="Camera_depth_frame"/>
  </joint>
  <link name="Camera_depth_optical_frame">
    <inertial>
      <origin rpy="0 0 0" xyz="0 0 0"/>
      <mass value="1e-6"/>
      <inertia ixx="1e-9" ixy="0" ixz="0" iyy="1e-9" iyz="0" izz="1e-9"/>
    </inertial>
  </link>
  <joint name="Camera_depth_optical_joint" type="fixed">
    <origin rpy="-1.5707963267948966 0 -1.5707963267948966" xyz="0 0 0"/>
    <parent link="Camera_depth_frame"/>
    <child link="Camera_depth_optical_frame"/>
  </joint>
  <link name="Camera_color_frame">
    <inertial>
      <origin rpy="0 0 0" xyz="0 0 0"/>
      <mass value="1e-6"/>
      <inertia ixx="1e-9" ixy="0" ixz="0" iyy="1e-9" iyz="0" izz="1e-9"/>
    </inertial>
  </link>
  <joint name="Camera_color_joint" type="fixed">
    <origin rpy="0 0 0" xyz="0 -0.0475 0"/>
    <parent link="Camera_depth_frame"/>
    <child link="Camera_color_frame"/>
  </joint>
  <link name="Camera_color_optical_frame">
    <inertial>
      <origin rpy="0 0 0" xyz="0 0 0"/>
      <mass value="1e-6"/>
      <inertia ixx="1e-9" ixy="0" ixz="0" iyy="1e-9" iyz="0" izz="1e-9"/>
    </inertial>
  </link>
  <joint name="Camera_color_optical_joint" type="fixed">
    <origin rpy="-1.5707963267948966 0 -1.5707963267948966" xyz="0 0 0"/>
    <parent link="Camera_color_frame"/>
    <child link="Camera_color_optical_frame"/>
  </joint>
</robot>
